[2024-04-18T07:23:09.268+0000] {taskinstance.py:1165} INFO - Dependencies all met for <TaskInstance: twitter_sentiment_analysis.EDA manual__2024-04-18T07:23:05.172548+00:00 [queued]>
[2024-04-18T07:23:09.281+0000] {taskinstance.py:1165} INFO - Dependencies all met for <TaskInstance: twitter_sentiment_analysis.EDA manual__2024-04-18T07:23:05.172548+00:00 [queued]>
[2024-04-18T07:23:09.281+0000] {taskinstance.py:1362} INFO - 
--------------------------------------------------------------------------------
[2024-04-18T07:23:09.283+0000] {taskinstance.py:1363} INFO - Starting attempt 1 of 1
[2024-04-18T07:23:09.284+0000] {taskinstance.py:1364} INFO - 
--------------------------------------------------------------------------------
[2024-04-18T07:23:09.303+0000] {taskinstance.py:1383} INFO - Executing <Task(PythonOperator): EDA> on 2024-04-18 07:23:05.172548+00:00
[2024-04-18T07:23:09.311+0000] {standard_task_runner.py:55} INFO - Started process 3934 to run task
[2024-04-18T07:23:09.314+0000] {standard_task_runner.py:82} INFO - Running: ['***', 'tasks', 'run', 'twitter_sentiment_analysis', 'EDA', 'manual__2024-04-18T07:23:05.172548+00:00', '--job-id', '4', '--raw', '--subdir', 'DAGS_FOLDER/SentimentAnalysis.py', '--cfg-path', '/tmp/tmpc6idoofv']
[2024-04-18T07:23:09.318+0000] {standard_task_runner.py:83} INFO - Job 4: Subtask EDA
[2024-04-18T07:23:09.381+0000] {task_command.py:376} INFO - Running <TaskInstance: twitter_sentiment_analysis.EDA manual__2024-04-18T07:23:05.172548+00:00 [running]> on host e23f925acc89
[2024-04-18T07:23:09.463+0000] {taskinstance.py:1592} INFO - Exporting the following env vars:
AIRFLOW_CTX_DAG_OWNER=***
AIRFLOW_CTX_DAG_ID=twitter_sentiment_analysis
AIRFLOW_CTX_TASK_ID=EDA
AIRFLOW_CTX_EXECUTION_DATE=2024-04-18T07:23:05.172548+00:00
AIRFLOW_CTX_TRY_NUMBER=1
AIRFLOW_CTX_DAG_RUN_ID=manual__2024-04-18T07:23:05.172548+00:00
[2024-04-18T07:23:09.465+0000] {taskinstance.py:1851} ERROR - Task failed with exception
Traceback (most recent call last):
  File "/home/airflow/.local/lib/python3.7/site-packages/airflow/operators/python.py", line 175, in execute
    return_value = self.execute_callable()
  File "/home/airflow/.local/lib/python3.7/site-packages/airflow/operators/python.py", line 193, in execute_callable
    return self.python_callable(*self.op_args, **self.op_kwargs)
  File "/opt/airflow/dags/SentimentAnalysis.py", line 18, in EDA
    train.dropna(inplace=True)
UnboundLocalError: local variable 'train' referenced before assignment
[2024-04-18T07:23:09.481+0000] {taskinstance.py:1406} INFO - Marking task as FAILED. dag_id=twitter_sentiment_analysis, task_id=EDA, execution_date=20240418T072305, start_date=20240418T072309, end_date=20240418T072309
[2024-04-18T07:23:09.497+0000] {standard_task_runner.py:105} ERROR - Failed to execute job 4 for task EDA (local variable 'train' referenced before assignment; 3934)
[2024-04-18T07:23:09.526+0000] {local_task_job.py:164} INFO - Task exited with return code 1
[2024-04-18T07:23:09.558+0000] {local_task_job.py:273} INFO - 0 downstream tasks scheduled from follow-on schedule check
